[ERROR] 2020-04-27 09:56:21,627 | /home/sharmila/frappe-bench/apps/frappe/frappe/utils/error.py:
Could not take error snapshot: invalid syntax (<string>, line 1)
Traceback (most recent call last):
  File "/home/sharmila/frappe-bench/apps/frappe/frappe/app.py", line 62, in application
    response = frappe.api.handle()
  File "/home/sharmila/frappe-bench/apps/frappe/frappe/api.py", line 55, in handle
    return frappe.handler.handle()
  File "/home/sharmila/frappe-bench/apps/frappe/frappe/handler.py", line 22, in handle
    data = execute_cmd(cmd)
  File "/home/sharmila/frappe-bench/apps/frappe/frappe/handler.py", line 61, in execute_cmd
    return frappe.call(method, **frappe.form_dict)
  File "/home/sharmila/frappe-bench/apps/frappe/frappe/__init__.py", line 1054, in call
    return fn(*args, **newargs)
  File "/home/sharmila/frappe-bench/apps/frappe/frappe/desk/form/save.py", line 22, in savedocs
    doc.save()
  File "/home/sharmila/frappe-bench/apps/frappe/frappe/model/document.py", line 273, in save
    return self._save(*args, **kwargs)
  File "/home/sharmila/frappe-bench/apps/frappe/frappe/model/document.py", line 326, in _save
    self.run_post_save_methods()
  File "/home/sharmila/frappe-bench/apps/frappe/frappe/model/document.py", line 926, in run_post_save_methods
    self.run_method("on_update")
  File "/home/sharmila/frappe-bench/apps/frappe/frappe/model/document.py", line 794, in run_method
    out = Document.hook(fn)(self, *args, **kwargs)
  File "/home/sharmila/frappe-bench/apps/frappe/frappe/model/document.py", line 1065, in composer
    return composed(self, method, *args, **kwargs)
  File "/home/sharmila/frappe-bench/apps/frappe/frappe/model/document.py", line 1048, in runner
    add_to_return_value(self, fn(self, *args, **kwargs))
  File "/home/sharmila/frappe-bench/apps/frappe/frappe/model/document.py", line 788, in <lambda>
    fn = lambda self, *args, **kwargs: getattr(self, method)(*args, **kwargs)
  File "/home/sharmila/frappe-bench/apps/frappe/frappe/core/doctype/doctype/doctype.py", line 286, in on_update
    self.update_fields_to_fetch()
  File "/home/sharmila/frappe-bench/apps/frappe/frappe/core/doctype/doctype/doctype.py", line 176, in update_fields_to_fetch
    frappe.db.sql(query)
  File "/home/sharmila/frappe-bench/apps/frappe/frappe/database/database.py", line 171, in sql
    self._cursor.execute(query)
  File "/home/sharmila/frappe-bench/env/lib/python3.6/site-packages/pymysql/cursors.py", line 170, in execute
    result = self._query(query)
  File "/home/sharmila/frappe-bench/env/lib/python3.6/site-packages/pymysql/cursors.py", line 328, in _query
    conn.query(q)
  File "/home/sharmila/frappe-bench/env/lib/python3.6/site-packages/pymysql/connections.py", line 517, in query
    self._affected_rows = self._read_query_result(unbuffered=unbuffered)
  File "/home/sharmila/frappe-bench/env/lib/python3.6/site-packages/pymysql/connections.py", line 732, in _read_query_result
    result.read()
  File "/home/sharmila/frappe-bench/env/lib/python3.6/site-packages/pymysql/connections.py", line 1075, in read
    first_packet = self.connection._read_packet()
  File "/home/sharmila/frappe-bench/env/lib/python3.6/site-packages/pymysql/connections.py", line 684, in _read_packet
    packet.check_error()
  File "/home/sharmila/frappe-bench/env/lib/python3.6/site-packages/pymysql/protocol.py", line 220, in check_error
    err.raise_mysql_exception(self._data)
  File "/home/sharmila/frappe-bench/env/lib/python3.6/site-packages/pymysql/err.py", line 109, in raise_mysql_exception
    raise errorclass(errno, errval)
pymysql.err.InternalError: (1054, "Unknown column 'source.project' in 'field list'")

During handling of the above exception, another exception occurred:

Traceback (most recent call last):
  File "/home/sharmila/frappe-bench/apps/frappe/frappe/utils/error.py", line 36, in make_error_snapshot
    snapshot = get_snapshot(exception)
  File "/home/sharmila/frappe-bench/apps/frappe/frappe/utils/error.py", line 132, in get_snapshot
    value = eval(value)
  File "<string>", line 1
    <built-in method with_traceback of InternalError object>
    ^
SyntaxError: invalid syntax
